Workbook

Sheet DATOS GENERALES
C1: ESTATUS | D1: CARRERA | E1: MATRÍCULA | F1: NOMBRE | G1: HORAS CONTABILIZADAS | H1: HORAS RESTANTES | I1: FECHA INICIO OFICIAL | J1: FECHA TÉRMINO OFICIAL | K1: TRIMESTRE INGRESO | L1: CORREO INSTITUCIONAL | M1: CORREO PERSONAL | N1: NO. TELEFÓNICO
C2: CONCLUIDO | D2: Ing. Física | E2: 2173003008 | F2: KARLA DANNEY ÁLVAREZ HERNÁNDEZ | G2: 0 | H2: =RESUMEN_GENERAL!$H$2-G2 -> 20 | I2: martes, abril 30, 2024 | J2: viernes, noviembre 29, 2024 | K2: 24-I | L2: al2173003008@azc.uam.mx | M2: danneyal548@gmail.com | N2: 2227227875
C3: CONCLUIDO | D3: Ing. Física | E3: 2202001912 | F3: CRISTOPHER JAIR ZAVALETA ROQUE | G3: 0 | H3: =RESUMEN_GENERAL!$H$2-G3 -> 20 | I3: viernes, julio 19, 2024 | J3: viernes, enero 31, 2025 | K3: 24-P | L3: al2202001912@azc.uam.mx | M3: cristopherzavaletaroque@gmail.com | N3: 7351433905
C4: CONCLUIDO | D4: Ing. Computación | E4: 2182003623 | F4: ALBERTO DANIEL GUTIERREZ RAMOS | G4: 0 | H4: =RESUMEN_GENERAL!$H$2-G4 -> 20 | I4: lunes, julio 22, 2024 | J4: miércoles, febrero 12, 2025 | K4: 24-P | L4: al2182003623@azc.uam.mx | M4: adgr_92@outlook.com | N4: 5539879408
C5: CONCLUIDO | D5: Ing. Industrial | E5: 2203000455 | F5: MARIA FERNANDA RODRÍGUEZ MORALES | G5: 0 | H5: =RESUMEN_GENERAL!$H$2-G5 -> 20 | I5: martes, julio 23, 2024 | J5: jueves, febrero 13, 2025 | K5: 24-P | L5: al2203000455@azc.uam.mx | M5: fercha2308@hotmail.com | N5: 5545900509
C6: CONCLUIDO | D6: Ing. Industrial | E6: 2192001962 | F6: SALMA ZUGEY RAMÍREZ LÓPEZ | G6: 0 | H6: =RESUMEN_GENERAL!$H$2-G6 -> 20 | I6: miércoles, agosto 7, 2024 | J6: viernes, febrero 28, 2025 | K6: 24-P | L6: al2192001962@azc.uam.mx | M6: sazu.amlas@gmail.com | N6: 5580032677
C7: CONCLUIDO | D7: Ing. Física | E7: 2193044210 | F7: FRANCISCO DONALDO JOSÉ ROMERO | G7: 0 | H7: =RESUMEN_GENERAL!$H$2-G7 -> 20 | I7: lunes, octubre 7, 2024 | J7: lunes, abril 28, 2025 | K7: 24-P | L7: al2193044210@azc.uam.mx | M7: al2193044210@azc.uam.mx | N7: 9531439483
C8: CONCLUIDO | D8: Ing. Mecánica | E8: 2173074678 | F8: CARLOS SANTIAGO ROMO HERNANDEZ | G8: 0 | H8: =RESUMEN_GENERAL!$H$2-G8 -> 20 | I8: lunes, octubre 28, 2024 | J8: lunes, mayo 19,2025 | K8: 24-O | L8: al2173074678@azc.uam.mx | M8: Santiago-romo@hotmail.com | N8: 5577127740
C9: CONCLUIDO | D9: Ing. Electrónica | E9: 2182003972 | F9: FERNANDA LETICIA SANCHEZ RAMOS | G9: 0 | H9: =RESUMEN_GENERAL!$H$2-G9 -> 20 | I9: lunes, octubre 28, 2024 | J9: lunes, mayo 19,2025 | K9: 24-O | L9: al2182003972@azc.uam.mx | M9: let23cr@gmail.com | N9: 5575541011
C10: CONCLUIDO | D10: Ing. Electrónica | E10: 2203033945 | F10: LEVY SEBASTIAN GONZÁLEZ PERIVÁN | G10: 0 | H10: =RESUMEN_GENERAL!$H$2-G10 -> 20 | I10: lunes, octubre 28, 2024 | J10: lunes, mayo 19,2025 | K10: 24-O | L10: al2203033945@azc.uam.mx | M10: runing735@gmail.com | N10: 5573451007
C11: CONCLUIDO | D11: Ing. Electrónica | E11: 2203033945 | F11: JESÚS JIMENEZ PRADO | G11: 0 | H11: =RESUMEN_GENERAL!$H$2-G11 -> 20 | I11: martes, octubre29, 2024 | J11: martes, mayo 20,2025 | K11: 24-O | L11: al2203033945@azc.uam.mx | M11: jesusjimpra@icloud.com | N11: 7444630468
C12: CONCLUIDO | D12: Ing. Computación | E12: 2143002726 | F12: ISAAC MAURICIO FUENTES GONZÁLEZ | G12: 0 | H12: =RESUMEN_GENERAL!$H$2-G12 -> 20 | I12: miércoles, noviembre 06, 2024 | J12: martes, 27 de mayo de 2025 | K12: 24-O | L12: al2143002726@azc.uam.mx | M12: isaackiller1107@gmail.com | N12: 5539345646
C13: CONCLUIDO | D13: Ing. Electrónica | E13: 2173039268 | F13: REINA CHUPIN CARBAJAL | G13: 0 | H13: =RESUMEN_GENERAL!$H$2-G13 -> 20 | I13: miércoles, noviembre 06, 2024 | J13: martes, 27 de mayo de 2025 | K13: 24-O | L13: al2173039268@azc.uam.mx | M13: reinachc32@gmail.com | N13: 7441650621
C14: CONCLUIDO | D14: Ing. Electrónica | E14: 2193040721 | F14: JORGE GUTIERREZ ROMERO | G14: 0 | H14: =RESUMEN_GENERAL!$H$2-G14 -> 20 | I14: miércoles, noviembre 06, 2024 | J14: martes, 27 de mayo de 2025 | K14: 24-O | L14: al2193040721@azc.uam.mx | M14: jgr5373@gmail.com | N14: 5626214540
C15: CONCLUIDO | D15: Ing. Mecánica | E15: 2193040909 | F15: DAVID RICARDO VAZQUEZ CESPEDES | G15: 0 | H15: =RESUMEN_GENERAL!$H$2-G15 -> 20 | I15: 45609 | J15: 45811 | K15: 24-O | L15: al2193040909@azc.uam.mx | M15: dvazquezcespedes5@gmail.com | N15: 5586880870
C16: CONCLUIDO | D16: Ing. Eléctrica | E16: 2193003595 | F16: DANIEL CASARREAL RODRÍGUEZ | G16: 0 | H16: =RESUMEN_GENERAL!$H$2-G16 -> 20 | I16: 45673 | J16: 45854 | K16: 24-O | L16: al2193003595@azc.uam.mx | M16: cxdanny230@gmail.com | N16: 5575155348
C17: CONCLUIDO | D17: Ing. Computación | E17: #VALUE! | F17: URIEL ISMAEL SOLÍS SILVA | G17: 0 | H17: =RESUMEN_GENERAL!$H$2-G17 -> 20 | I17: 45684 | J17: 45891 | K17: 25-I | L17: al2163034037@azc.uam.mx | N17: 5619313139
C18: CONCLUIDO | D18: Ing. Mecánica | E18: #VALUE! | F18: JESSICA HERNANDEZ SAAB | G18: 0 | H18: =RESUMEN_GENERAL!$H$2-G18 -> 20 | I18: 45742 | J18: 45954 | K18: 25-I | L18: al2173008941@azc.uam.mx | N18: 5562051863
C19: CONCLUIDO | D19: Ing. Física | E19: #VALUE! | F19: SERGIO EMILIANO BALTAZAR GARCELA | G19: 0 | H19: =RESUMEN_GENERAL!$H$2-G19 -> 20 | I19: 45742 | J19: 45954 | K19: 25-I | L19: al2152000365@azc.uam.mx | N19: 5545500269
C20: CONCLUIDO | D20: Ing. Industrial | E20: #VALUE! | F20: ÁNGEL NOGUEZ MENDIZABAL | G20: 0 | H20: =RESUMEN_GENERAL!$H$2-G20 -> 20 | I20: 45754 | J20: 45961 | K20: 25-I | L20: al2183001472@azc.uam.mx | M20: eldrnoguez@gmail.com | N20: 5583723328
C21: CONCLUIDO | D21: Ing. Mecánica | E21: 2182005967 | F21: MARCOS ÁLVAREZ VIDAL | G21: 0 | H21: =RESUMEN_GENERAL!$H$2-G21 -> 20 | I21: 45768 | K21: 25-I | L21: al2182005967@azc.uam.mx
C22: CONCLUIDO | D22: Ing. Electrónica | E22: 2173076707 | F22: JOSÉ ARMANDO VALENCIA GONZÁLEZ | G22: 0 | H22: =RESUMEN_GENERAL!$H$2-G22 -> 20 | I22: 45810 | J22: 46038 | K22: 25-I | L22: al2173076707@azc.uam.mx
C23: CONCLUIDO | D23: Ing. Electrónica | E23: 2212004434 | F23: ESAU HEJECATL JUÁREZ AGUILAR | G23: 0 | H23: =RESUMEN_GENERAL!$H$2-G23 -> 20 | I23: 45810 | J23: 46038 | K23: 25-I | L23: al2212001880@azc.uam.mx | M23: esaujuares@gmail.com | N23: 5530748953
C24: CONCLUIDO | D24: Ing. Electrónica | E24: 2182002288 | F24: EDUARDO CORTEZ MONTAÑO | G24: 0 | H24: =RESUMEN_GENERAL!$H$2-G24 -> 20 | I24: 45806 | J24: 46020 | K24: 25-I | L24: al2182002288@azc.uam.mx
C25: CONCLUIDO | D25: Ing. Electrónica | E25: 2192007624 | F25: MANUEL CRUZ GUADARRAMA | G25: 0 | H25: =RESUMEN_GENERAL!$H$2-G25 -> 20 | I25: 45799 | J25: 46013 | K25: 25-I | L25: al2192007624@azc.uam.mx
C26: CONCLUIDO | D26: Ing. Electrónica | E26: #VALUE! | F26: ARMANDO PÉREZ GARCÍA | G26: 0 | H26: =RESUMEN_GENERAL!$H$2-G26 -> 20 | I26: 45817 | J26: 46052 | K26: 25-I | L26: al2212001880@azc.uam.mx
C27: CONCLUIDO | D27: Ing. Industrial | E27: #VALUE! | F27: ALEXIS ARIEL HERNÁNDEZ SALGADO | G27: 0 | H27: =RESUMEN_GENERAL!$H$2-G27 -> 20 | I27: 45866 | J27: 45729 | K27: 25-P | L27: al2182002948@azc.uam.mx | M27: hernandezsalgadoalexis@gmail.com | N27: 5541454262
C28: CONCLUIDO | D28: Ing. Computación | E28: #VALUE! | F28: RONALDO JAVIER CRUZ ARREOLA | G28: 0 | H28: =RESUMEN_GENERAL!$H$2-G28 -> 20 | I28: 45943 | J28: 46150 | K28: 25-O | L28: al2222004722@azc.uam.mx | M28: ronaldojca2901@gmail.com | N28: 5548863565
C29: CONCLUIDO | D29: Ing. Electrónica | E29: #VALUE! | F29: EDUARDO LUNA REYES | G29: 0 | H29: =RESUMEN_GENERAL!$H$2-G29 -> 20 | I29: 45943 | J29: 46150 | K29: 25-O | L29: al2142000040@azc.uam.mx | M29: eduardolunareyes1@gmail.com | N29: 5572162818
C30: CONCLUIDO | D30: Ing. Electrónica | E30: 2213032521 | F30: ÁNGEL GAEL ALMONACID MENDOZA | G30: 0 | H30: =RESUMEN_GENERAL!$H$2-G30 -> 20 | I30: 45943 | J30: 46150 | K30: 25-O | L30: al2213032521@azc.uam.mx | N30: 5533053156
C31: CONCLUIDO | D31: ing. Electrónica | E31: 2193004190 | F31: RAFAEL PIÑA CALIXTO | G31: 0 | H31: =RESUMEN_GENERAL!$H$2-G31 -> 20 | I31: 45978 | J31: 46178 | K31: 25-O | L31: al2193004190@azc.uam.mx | M31: rafp.c2001@gmail.com | N31: 5552152907
C32: CONCLUIDO | D32: ing. Electrónica | E32: 2173076565 | F32: CINDY MADIÁN MALDONADO ROSAS | G32: 0 | H32: =RESUMEN_GENERAL!$H$2-G32 -> 20 | I32: 45964 | J32: 46150 | K32: 25-O
C33: CONCLUIDO | D33: ing. Electrónica | E33: 2192007393 | F33: JENNIFER RUBÍ MORALEZ VERA | G33: 0 | H33: =RESUMEN_GENERAL!$H$2-G33 -> 20 | I33: lunes, novembre 10, 2025 | J33: miercoles, mayo 13, 2025 | K33: 25-O
C34: CONCLUIDO | D34: ing. Electrónica | E34: 2203000348 | F34: DAYANA SOLORZA NOLASCO | G34: 0 | H34: =RESUMEN_GENERAL!$H$2-G34 -> 20 | I34: 45999 | J34: 46188 | K34: 25-O | L34: al2203000348@azc.uam.mx
C35: CONCLUIDO | D35: Ing. Industrial | E35: 2212006803 | F35: ARTURO ORTEGA PÉREZ | G35: 0 | H35: =RESUMEN_GENERAL!$H$2-G35 -> 20 | I35: 46000 | J35: 46174 | K35: 25-O | L35: al2212006803@azc.uam.mx | N35: 5559457627
C36: CONCLUIDO | D36: Ing. Eléctrica | E36: 2123031703 | F36: HILARIO MARTIN CRUZ CRUZ | G36: 0 | H36: =RESUMEN_GENERAL!$H$2-G36 -> 20 | I36: 46003 | K36: 25-O
C37: CONCLUIDO | D37: ing. Electrónica | E37: 2183042213 | F37: FERNANDO GUTIÉRREZ HERRERA | G37: 0 | H37: =RESUMEN_GENERAL!$H$2-G37 -> 20 | I37: 46048 | J37: 46227 | K37: 26-I | L37: al2183042213@azc.uam.mx | M37: kamina.gh27@outlook.com | N37: 5587734257
C38: CONCLUIDO | D38: Ing. Industrial | E38: 2213032683 | F38: PERCY OSIEL CHÁVEZ GONZÁLEZ | G38: 20 | H38: =RESUMEN_GENERAL!$H$2-G38 -> 0 | I38: 46062 | J38: 46241 | K38: 26-I | L38: al2213032683@gmail.com | M38: percygonzalez999@gmail.com | N38: 5524639048
C39: CONCLUIDO | D39: Ing. Industrial | E39: 2202001994 | F39: JAVIER GUERRERO SALAS | G39: ='JAVIER G.S'!R1 -> 20.015046 | H39: =RESUMEN_GENERAL!$H$2-G39 -> -0.015046296 | I39: 46083 | J39: 46297 | K39: 26-I | L39: al2202001994@azc.uam.mx | M39: jgs27052002@gmail.com | N39: 5575229694
C40: ACTIVO | D40: ing. Electrónica | E40: 2192007142 | F40: KATHERINE MENDEZ MARQUEZ | G40: ='KATHERINE M.M'!R1 -> 20.142986 | H40: =RESUMEN_GENERAL!$H$2-G40 -> -0.14298611 | I40: 46097 | J40: 46311 | K40: 26-I | L40: al2192007142@azc.uam.mx | M40: katherinemend25@gmail.com | N40: 5540382947
...

Sheet RESUMEN_GENERAL
H1: TOTAL DE HORAS A CUBRIR
H2: 20
B3: NOMBRE | C3: HORAS CONTABILIZADAS | D3: HORAS RESTANTES | E3: AVANCE
B4: ALEJANDRO RAMOS MAYEN | C4: ='ALEJANDRO R.M'!R1 -> 15.981944 | D4: =$H$2-C4 -> 4.0180556 | E4: =C4/$H$2 -> 0.79909722
B5: CESAR YAIR ESPINOSA MARTINEZ | C5: ='CESAR Y.E.M'!R1 -> 13.194109 | D5: =$H$2-C5 -> 6.8058912 | E5: =C5/$H$2 -> 0.65970544
B6: CHRISTIAN GONZÁLEZ GUTIÉRREZ | C6: ='CHRISTIAN G.G'!R1 -> 15.721609 | D6: =$H$2-C6 -> 4.2783912 | E6: =C6/$H$2 -> 0.78608044
B7: FÁTIMA PACHECO ZACARÍAS | C7: ='FÁTIMA P.Z'!R1 -> 19.842384 | D7: =$H$2-C7 -> 0.15761574 | E7: =C7/$H$2 -> 0.99211921
B8: FERNANDO JAVIER RAMIREZ GARCIA | C8: ='FERNANDO J.R.G'!R1 -> 14.90603 | D8: =$H$2-C8 -> 5.0939699 | E8: =C8/$H$2 -> 0.7453015
B9: KARLA YAMILET AGUILAR RAMÍREZ | C9: ='KARLA Y.A.R'!R1 -> 14.630428 | D9: =$H$2-C9 -> 5.3695718 | E9: =C9/$H$2 -> 0.73152141
B10: KATHERINE MENDEZ MARQUEZ | C10: ='KATHERINE M.M'!R1 -> 20.142986 | D10: =$H$2-C10 -> -0.14298611 | E10: =C10/$H$2 -> 1.0071493
B11: LUDWING PINEDA CUEVAS | C11: ='LUDWING P.C'!R1 -> 3.1560185 | D11: =$H$2-C11 -> 16.843981 | E11: =C11/$H$2 -> 0.15780093
B12: LUIS FERNANDO CASTILLO GARCÍA | C12: ='LUIS F.C.G'!R1 -> 15.661076 | D12: =$H$2-C12 -> 4.3389236 | E12: =C12/$H$2 -> 0.78305382
B13: MARIA NATALIA CABRERA MONJARAS | C13: ='MARIA N.C.M'!R1 -> 13.335706 | D13: =$H$2-C13 -> 6.664294 | E13: =C13/$H$2 -> 0.6667853
B14: MISAEL RIVERA LÓPEZ | C14: ='MISAEL R.L'!R1 -> 9.0679977 | D14: =$H$2-C14 -> 10.932002 | E14: =C14/$H$2 -> 0.45339988
B15: RAFAEL EDUARDO LAGUNAS GÓMEZ | C15: ='RAFAEL E.L.G'!R1 -> 15.218137 | D15: =$H$2-C15 -> 4.7818634 | E15: =C15/$H$2 -> 0.76090683
B16: CARLOS CRISTOPHER TERRAZAS MARTINEZ | C16: ='CARLOS C.T.M'!R1 -> 2.5592477 | D16: =$H$2-C16 -> 17.440752 | E16: =C16/$H$2 -> 0.12796238

Sheet COPIA
Q1: TOTAL CONTABILIZADO: | R1: =SUM(P:P) -> 0
A2: FECHA | B2: ENTRADA 1 | C2: SALIDA 1 | D2: TOTAL 1 | E2: ENTRADA 2 | F2: SALIDA 2 | G2: TOTAL 2 | H2: ENTRADA 3 | I2: SALIDA 3 | J2: TOTAL 3 | K2: TOTAL HORAS DIARIAS | L2: AJUSTE (-) | N2: JUSTIFICACIÓN | P2: TOTAL DE SEMANA
A3: 46286
A4: 46287
A5: 46288
A6: 46289
A7: 46290
P9: =SUMPRODUCT(VALUE(K3:K7))-(SUM(L3:L7)) -> 0
A10: 46293
A11: 46294
A12: 46295
A13: 46296
A14: 46297
P16: =SUMPRODUCT(VALUE(K10:K14))-(SUM(L10:L14)) -> 0
A17: 46300
A18: 46301
A19: 46302
A20: 46303
A21: 46304
P23: =SUMPRODUCT(VALUE(K17:K21))-(SUM(L17:L21)) -> 0
A24: 46307
A25: 46308
A26: 46309
A27: 46310
A28: 46311
P30: =SUMPRODUCT(VALUE(K24:K28))-(SUM(L24:L28)) -> 0
A31: 46314
A32: 46315
A33: 46316
A34: 46317
A35: 46318
P37: =SUMPRODUCT(VALUE(K31:K35))-(SUM(L31:L35)) -> 0
A38: 46321
A39: 46322
A40: 46323
A41: 46324
A42: 46325
P44: =SUMPRODUCT(VALUE(K38:K42))-(SUM(L38:L42)) -> 0
A45: 46328
A46: 46329
...

Sheet ALEJANDRO R.M
A1: ALEJANDRO RAMOS MAYEN | Q1: TOTAL CONTABILIZADO: | R1: =SUM(P:P) -> 15.981944
A2: FECHA | B2: ENTRADA 1 | C2: SALIDA 1 | D2: TOTAL 1 | E2: ENTRADA 2 | F2: SALIDA 2 | G2: TOTAL 2 | H2: ENTRADA 3 | I2: SALIDA 3 | J2: TOTAL 3 | K2: TOTAL HORAS DIARIAS | L2: AJUSTE (-) | N2: JUSTIFICACIÓN | P2: TOTAL DE SEMANA
A3: 46286 | B3: 06:37:00 | C3: 10:51:00 | D3: 04:14:00 | K3: 04:14:00 | L3: 0.0097222222 | P3: 12.401123
A4: 46287 | B4: 06:30:00 | C4: 10:59:00 | D4: 04:29:00 | K4: 04:29:00 | L4: 0.020138889
A5: 46288 | B5: 07:03:00 | C5: 10:49:00 | D5: 03:46:00 | K5: 03:46:00
A6: 46289 | B6: 06:24:00 | C6: 11:30:00 | D6: 05:06:00 | K6: 05:06:00
A7: 46290 | B7: 06:32:00 | C7: 10:50:00 | D7: 04:18:00 | K7: 04:18:00 | L7: 0.0125
P9: =SUMPRODUCT(VALUE(K3:K7))-(SUM(L3:L7)) -> 0.86944444
A10: 46293 | B10: 06:50:28 | C10: 11:00:41 | D10: 04:10:13 | K10: 04:10:13 | L10: 0.0070949074 | N10: Tiempo no justificado
A11: 46294 | B11: 06:35:58 | C11: 11:01:41 | D11: 04:25:43 | K11: 04:25:43 | L11: 0.017361111 | N11: Tiempo no justificado
A12: 46295 | B12: 06:38:11 | C12: 11:00:00 | D12: 00:00:00 | E12: 06:39:23 | F12: 11:00:16 | G12: 04:20:53 | K12: 04:20:53 | L12: 0.013888889 | N12: Tiempo no justificado
A13: 46296 | B13: 06:40:44 | C13: 11:00:38 | D13: 04:19:54 | K13: 04:19:54 | L13: 0.013194444 | N13: Tiempo no justificado
A14: 46297 | B14: 06:35:47 | C14: 11:03:39 | D14: 04:27:52 | K14: 04:27:52 | L14: 0.01875 | N14: Tiempo no justificado
P16: =SUMPRODUCT(VALUE(K10:K14))-(SUM(L10:L14)) -> 0.8356713
A17: 46300 | B17: 06:41:26 | C17: 11:11:45 | D17: 04:30:19 | K17: 04:30:19
A18: 46301 | B18: 07:17:28 | C18: 11:00:12 | D18: 03:42:44 | K18: 03:42:44
A19: 46302 | B19: 06:33:55 | C19: 11:02:46 | D19: 04:28:51 | K19: 04:28:51
A20: 46303 | B20: 07:07:25 | C20: 11:00:11 | D20: 03:52:46 | K20: 03:52:46
A21: 46304
P23: =SUMPRODUCT(VALUE(K17:K21))-(SUM(L17:L21)) -> 0.69074074
A24: 46307
A25: 46308 | B25: 06:38:41 | C25: 11:59:53 | D25: 05:21:12 | K25: 05:21:12 | L25: 0.014722222 | N25: Tiempo no justificado
A26: 46309 | B26: 06:34:57 | C26: 10:58:54 | D26: 04:23:57 | K26: 04:23:57 | L26: 0.016631944 | N26: Tiempo no justificado
A27: 46310 | B27: 06:57:09 | C27: 10:59:57 | D27: 04:02:48 | K27: 04:02:48 | L27: 0.041666667 | N27: Ausencia injustificada
A28: 46311 | B28: 06:42:03 | C28: 10:59:33 | D28: 04:17:30 | K28: 04:17:30
P30: =SUMPRODUCT(VALUE(K24:K28))-(SUM(L24:L28)) -> 0.68076389
A31: 46314 | B31: 06:56:48 | C31: 11:01:20 | D31: 04:04:32 | K31: 04:04:32
A32: 46315 | B32: 06:41:40 | C32: 10:59:20 | D32: 04:17:40 | K32: 04:17:40 | L32: 0.011805556 | N32: Tiempo no justificado
A33: 46316 | B33: 06:35:21 | C33: 11:00:12 | D33: 04:24:51 | K33: 04:24:51 | L33: 0.016666667 | N33: Tiempo no justificado
A34: 46317 | B34: 06:46:36
A35: 46318
P37: =SUMPRODUCT(VALUE(K31:K35))-(SUM(L31:L35)) -> 0.50420139
A38: 46321
A39: 46322
A40: 46323
A41: 46324
A42: 46325
P44: =SUMPRODUCT(VALUE(K38:K42))-(SUM(L38:L42)) -> 0
A45: 46328
A46: 46329
...

Sheet CESAR Y.E.M
A1: CESAR YAIR ESPINOSA MARTINEZ | Q1: TOTAL CONTABILIZADO: | R1: =SUM(P:P) -> 13.194109
A2: FECHA | B2: ENTRADA 1 | C2: SALIDA 1 | D2: TOTAL 1 | E2: ENTRADA 2 | F2: SALIDA 2 | G2: TOTAL 2 | H2: ENTRADA 3 | I2: SALIDA 3 | J2: TOTAL 3 | K2: TOTAL HORAS DIARIAS | L2: AJUSTE (-) | N2: JUSTIFICACIÓN | P2: TOTAL DE SEMANA
A3: 46286 | B3: 15:18:00 | C3: 20:50:00 | D3: =C3-B3 -> 0.23055556 | K3: =D3+G3+J3 -> 0.23055556 | P3: 9.0633449
A4: 46287 | B4: 15:13:00 | C4: 20:18:00 | D4: =C4-B4 -> 0.21180556 | K4: =D4+G4+J4 -> 0.21180556 | L4: 0.0034722222
A5: 46288 | B5: 15:16:00 | C5: 20:18:00 | D5: =C5-B5 -> 0.20972222 | K5: =D5+G5+J5 -> 0.20972222 | L5: 0.0013888889
A6: 46289 | B6: 15:16:00 | C6: 20:20:00 | D6: =C6-B6 -> 0.21111111 | K6: =D6+G6+J6 -> 0.21111111 | L6: 0.0027777778
A7: 46290 | B7: 15:21:00 | C7: 20:33:00 | D7: =C7-B7 -> 0.21666667 | K7: =D7+G7+J7 -> 0.21666667 | L7: 0.0083333333
P9: =SUMPRODUCT(VALUE(K3:K7))-(SUM(L3:L7)) -> 1.0638889
A10: 46293 | B10: 15:22:17 | C10: 20:31:49 | D10: 05:09:32 | K10: 05:09:32 | L10: 0.0066203704 | N10: Solo 1 hora Justificada
A11: 46294 | B11: 15:22:19 | C11: 20:30:20 | D11: 05:08:01 | K11: 05:08:01 | L11: 0.0055671296 | N11: Solo 1 hora Justificada
A12: 46295 | B12: 15:24:53 | C12: 20:31:17 | D12: 05:06:24 | K12: 05:06:24 | L12: 0.0044444444 | N12: Solo 1 hora Justificada
A13: 46296 | B13: 15:21:57 | C13: 20:39:52 | D13: 05:17:55 | K13: 05:17:55 | L13: 0.011805556 | N13: Solo 1 hora Justificada
A14: 46297 | B14: 16:38:09 | C14: 20:31:08 | D14: 03:52:59 | K14: 03:52:59
P16: =SUMPRODUCT(VALUE(K10:K14))-(SUM(L10:L14)) -> 0.99576389
A17: 46300 | B17: 15:38:58 | C17: 20:32:17 | D17: 04:53:19 | K17: 04:53:19 | N17: Solo 1 hora Justificada
A18: 46301 | B18: 15:55:41 | C18: 20:37:23 | D18: 04:41:42 | K18: 04:41:42 | N18: Tiempo jutificdo
A19: 46302 | B19: 15:22:05 | C19: 20:34:04 | D19: 05:11:59 | K19: 05:11:59 | L19: 0.0076388889 | N19: Solo 1 hora Justificada
A20: 46303 | B20: 15:34:45 | C20: 20:29:50 | D20: 04:55:05 | K20: 04:55:05 | N20: Tiempo jutificdo
A21: 46304 | B21: 15:29:46 | C21: 20:31:07 | D21: 05:01:21 | K21: 05:01:21 | N21: Tiempo jutificdo
P23: =SUMPRODUCT(VALUE(K17:K21))-(SUM(L17:L21)) -> 1.0225231
A24: 46307
A25: 46308 | B25: 16:35:46 | C25: 20:30:45 | D25: 03:54:59 | K25: 03:54:59
A26: 46309 | B26: 16:23:02 | C26: 20:31:50 | D26: 04:08:48 | K26: 04:08:48
A27: 46310 | B27: 16:54:12 | C27: 21:00:27 | D27: 04:06:15 | K27: 04:06:15
A28: 46311 | B28: 16:36:08 | C28: 20:31:10 | D28: 03:55:02 | K28: 03:55:02
P30: =SUMPRODUCT(VALUE(K24:K28))-(SUM(L24:L28)) -> 0.67018519
A31: 46314 | B31: 13:31:44 | C31: 17:32:35 | D31: 04:00:51 | K31: 04:00:51
A32: 46315
A33: 46316 | B33: 15:32:02 | C33: 20:36:05 | D33: 05:04:03 | K33: 05:04:03
A34: 46317
A35: 46318
P37: =SUMPRODUCT(VALUE(K31:K35))-(SUM(L31:L35)) -> 0.37840278
A38: 46321
A39: 46322
A40: 46323
A41: 46324
A42: 46325
P44: =SUMPRODUCT(VALUE(K38:K42))-(SUM(L38:L42)) -> 0
A45: 46328
A46: 46329
...

Sheet CHRISTIAN G.G
A1: CHRISTIAN GONZÁLEZ GUTIÉRREZ | Q1: TOTAL CONTABILIZADO: | R1: =SUM(P:P) -> 15.721609
A2: FECHA | B2: ENTRADA 1 | C2: SALIDA 1 | D2: TOTAL 1 | E2: ENTRADA 2 | F2: SALIDA 2 | G2: TOTAL 2 | H2: ENTRADA 3 | I2: SALIDA 3 | J2: TOTAL 3 | K2: TOTAL HORAS DIARIAS | L2: AJUSTE (-) | N2: JUSTIFICACIÓN | P2: TOTAL DE SEMANA
A3: 46286 | B3: 11:45:00 | C3: 12:49:00 | D3: 01:04:00 | E3: 14:05:00 | F3: 17:17:00 | G3: 03:12:00 | K3: 04:16:00 | L3: 00:16.00 | P3: 12.278692
A4: 46287 | B4: 06:35:00 | C4: 11:29:00 | D4: 04:54:00 | K4: 04:54:00
A5: 46288 | B5: 13:09:00 | C5: 17:21:00 | D5: 04:12:00 | K5: 04:12:00 | L5: 0.0083333333
A6: 46289 | B6: 06:43:00 | C6: 11:31:00 | D6: 04:48:00 | K6: 04:48:00
A7: 46290 | B7: 13:15:00 | C7: 17:16:00 | D7: 04:01:00 | K7: 04:01:00
P9: =SUMPRODUCT(VALUE(K3:K7))-(SUM(L3:L7)) -> 0.91597222
A10: 46293 | B10: 11:50:00 | C10: 13:00:04 | D10: 01:10:04 | E10: 14:25:45 | F10: 17:26:23 | G10: 03:00:38 | K10: 04:10:42 | L10: 0.0074305556
A11: 46294 | B11: 06:44:17 | C11: 11:01:46 | D11: 04:17:29 | K11: 04:17:29 | L11: 0.012141204
A12: 46295 | B12: 13:16:02 | C12: 17:30:24 | D12: 04:14:22 | K12: 04:14:22 | L12: 0.0099768519
A13: 46296 | B13: 06:55:52 | C13: 11:00:54 | D13: 04:05:02 | K13: 04:05:02 | L13: 0.0034953704
A14: 46297 | B14: 13:26:34 | C14: 17:31:41 | D14: 04:05:07 | K14: 04:05:07 | L14: 0.0035532407
P16: =SUMPRODUCT(VALUE(K10:K14))-(SUM(L10:L14)) -> 0.83333333
A17: 46300 | B17: 11:49:02 | C17: 13:00:01 | D17: 01:10:59 | E17: 14:36:03 | F17: 17:30:15 | G17: 02:54:12 | K17: 04:05:11
A18: 46301 | B18: 06:46:45 | C18: 11:00:16 | D18: 04:13:31 | K18: 04:13:31 | L18: 0.0090277778
A19: 46302 | B19: 13:14:08 | C19: 17:28:17 | D19: 04:14:09 | K19: 04:14:09 | L19: 0.0097222222
A20: 46303 | B20: 06:45:20 | C20: 11:00:15 | D20: 04:14:55 | K20: 04:14:55 | L20: 0.0097222222
A21: 46304 | B21: 13:32:58 | C21: 17:29:23 | D21: 03:56:25 | K21: 03:56:25
P23: =SUMPRODUCT(VALUE(K17:K21))-(SUM(L17:L21)) -> 0.83554398
A24: 46307
A25: 46308 | B25: 07:04:04 | C25: 11:00:44 | D25: 03:56:40 | K25: 03:56:40
A26: 46309 | B26: 13:19:00 | C26: 17:29:22 | D26: 04:10:22 | K26: 04:10:22
A27: 46310 | B27: 06:45:51 | C27: 11:00:01 | D27: 04:14:10 | K27: 04:14:10 | L27: 0.041666667 | N27: Ausencia injustificada
A28: 46311 | B28: 13:25:48 | C28: 17:33:24 | D28: 04:07:36 | K28: 04:07:36
P30: =SUMPRODUCT(VALUE(K24:K28))-(SUM(L24:L28)) -> 0.645
A31: 46314 | B31: 11:56:10 | C31: 12:59:45 | D31: 01:03:35 | K31: 01:03:35
A32: 46315 | B32: 06:56:11 | C32: 10:59:25 | D32: 04:03:14 | K32: 04:03:14
A33: 46316 | B33: 13:26:29 | D33: 00:00:00 | K33: 00:00:00
A34: 46317 | B34: 06:37:53 | D34: 00:00:00 | K34: 00:00:00
A35: 46318
P37: =SUMPRODUCT(VALUE(K31:K35))-(SUM(L31:L35)) -> 0.21306713
A38: 46321
A39: 46322
A40: 46323
A41: 46324
A42: 46325
P44: =SUMPRODUCT(VALUE(K38:K42))-(SUM(L38:L42)) -> 0
A45: 46328
A46: 46329
...

Sheet FÁTIMA P.Z
A1: FÁTIMA PACHECO ZACARÍAS | Q1: TOTAL CONTABILIZADO: | R1: =SUM(P:P) -> 19.842384
A2: FECHA | B2: ENTRADA 1 | C2: SALIDA 1 | D2: TOTAL 1 | E2: ENTRADA 2 | F2: SALIDA 2 | G2: TOTAL 2 | H2: ENTRADA 3 | I2: SALIDA 3 | J2: TOTAL 3 | K2: TOTAL HORAS DIARIAS | L2: AJUSTE (-) | N2: JUSTIFICACIÓN | P2: TOTAL DE SEMANA
A3: 46286 | B3: 08:54:00 | C3: 09:44:00 | D3: 00:50:00 | E3: 15:53:00 | F3: 17:16:00 | G3: 01:23:00 | K3: 02:13:00 | P3: 16.383646
A4: 46287 | B4: 11:20:00 | C4: 15:18:00 | D4: 03:58:00 | K4: 03:58:00
A5: 46288 | B5: 08:54:00 | C5: 09:40:00 | D5: 00:46:00 | E5: 12:51:00 | F5: 14:19:00 | G5: 01:28:00 | H5: 16:13:00 | I5: 17:17:00 | J5: 01:04:00 | K5: 03:18:00
A6: 46289 | B6: 08:57:00 | C6: 09:43:00 | D6: 00:46:00 | E6: 11:22:00 | F6: 14:26:00 | G6: 03:04:00 | K6: 03:50:00
A7: 46290 | B7: 08:51:00 | C7: 09:46:00 | D7: 00:55:00 | E7: 12:59:00 | F7: 14:12:00 | G7: 01:13:00 | H7: 16:12:00 | I7: 17:14:00 | J7: 01:02:00 | K7: 03:10:00
P9: =SUMPRODUCT(VALUE(K3:K7))-(SUM(L3:L7)) -> 0.68680556
A10: 46293 | B10: 09:06:35 | C10: 09:59:35 | D10: 00:53:00 | E10: 16:13:55 | F10: 17:22:53 | G10: =F10-E10 -> 0.047893519 | K10: =D10+G10+J10 -> 0.084699074
A11: 46294 | G11: =F11-E11 -> 0 | K11: =D11+G11+J11 -> 0
A12: 46295 | B12: 09:06:57 | C12: 09:56:32 | D12: 00:49:35 | E12: 13:20:25 | F12: 14:33:26 | G12: =F12-E12 -> 0.050706019 | H12: 16:12:44 | I12: 18:58:17 | J12: 02:45:33 | K12: =D12+G12+J12 -> 0.20010417
A13: 46296 | B13: 09:09:02 | C13: 10:03:12 | D13: 00:54:10 | E13: 11:28:46 | F13: 15:47:40 | G13: =F13-E13 -> 0.17979167 | K13: =D13+G13+J13 -> 0.21740741
A14: 46297 | B14: 09:06:55 | C14: 10:02:30 | D14: 00:55:35 | E14: 12:59:39 | F14: 0.67222222 | G14: =F14-E14 -> 0.13079861 | H14: 16:08:56 | I14: 17:31:47 | J14: 01:22:51 | K14: =D14+G14+J14 -> 0.22693287
P16: =SUMPRODUCT(VALUE(K10:K14))-(SUM(L10:L14)) -> 0.72914352
A17: 46300 | B17: 09:01:47 | D17: 00:00:00 | E17: 09:04:10 | F17: 09:56:38 | G17: 00:52:28 | H17: 12:29:40 | I17: 13:00:30 | J17: 00:30:50 | K17: 01:23:18
A18: 46301 | B18: 09:12:44 | C18: 09:59:58 | D18: 00:47:14 | E18: 11:27:03 | F18: 17:32:33 | G18: 06:05:30 | K18: 06:52:44
A19: 46302 | B19: 09:01:53 | C19: 09:58:26 | D19: 00:56:33 | E19: 11:31:28 | F19: 17:29:07 | G19: 05:57:39 | K19: 06:54:12
A20: 46303 | B20: 09:09:33 | C20: 10:02:35 | D20: 00:53:02 | E20: 11:21:13 | F20: 17:36:05 | G20: 06:14:52 | K20: 07:07:54
A21: 46304 | B21: 11:29:22 | C21: 14:32:04 | D21: 03:02:42 | E21: 16:10:40 | F21: 17:29:08 | G21: 01:18:28 | K21: 04:21:10
P23: =SUMPRODUCT(VALUE(K17:K21))-(SUM(L17:L21)) -> 1.110625
A24: 46307
A25: 46308 | B25: 09:14:52 | C25: 17:03:57 | D25: =C25-B25 -> 0.32575231 | K25: =D25 -> 0.32575231
A26: 46309 | B26: 09:04:12 | C26: 10:05:51 | D26: =C26-B26 -> 0.0428125 | E26: 13:04:06 | F26: 14:33:01 | G26: 01:28:55 | H26: 16:06:49 | I26: 17:29:27 | J26: 01:22:38 | K26: 03:53:12
A27: 46310 | B27: 08:59:29 | C27: 09:57:53 | D27: =C27-B27 -> 0.040555556 | E27: 11:30:43 | F27: 15:31:47 | G27: 04:01:04 | K27: 04:59:28
A28: 46311 | B28: 09:08:47 | C28: 10:16:47 | D28: =C28-B28 -> 0.047222222 | E28: 11:25:51 | F28: 11:27:09 | G28: 00:01:18 | H28: 13:16:51 | I28: 14:39:58 | J28: 01:23:07 | K28: 02:32:25
P30: =SUMPRODUCT(VALUE(K24:K28))-(SUM(L24:L28)) -> 0.80150463
A31: 46314 | B31: 09:07:18 | C31: 10:06:46 | D31: 00:59:28 | E31: 16:15:43 | F31: 17:32:43 | G31: 01:17:00 | K31: 02:16:28
A32: 46315 | B32: 09:08:47 | C32: 10:00:28 | D32: 00:51:41 | E32: 11:26:23 | F32: 0.66666667 | G32: 00:00:00 | K32: 00:51:41
A33: 46316
A34: 46317
A35: 46318
P37: =SUMPRODUCT(VALUE(K31:K35))-(SUM(L31:L35)) -> 0.13065972
A38: 46321
A39: 46322
A40: 46323
A41: 46324
A42: 46325
P44: =SUMPRODUCT(VALUE(K38:K42))-(SUM(L38:L42)) -> 0
A45: 46328
A46: 46329
...

Sheet FERNANDO J.R.G
A1: FERNANDO JAVIER RAMIREZ GARCIA | Q1: TOTAL CONTABILIZADO: | R1: =SUM(P:P) -> 14.90603
A2: FECHA | B2: ENTRADA 1 | C2: SALIDA 1 | D2: TOTAL 1 | E2: ENTRADA 2 | F2: SALIDA 2 | G2: TOTAL 2 | H2: ENTRADA 3 | I2: SALIDA 3 | J2: TOTAL 3 | K2: TOTAL HORAS DIARIAS | L2: AJUSTE (-) | N2: JUSTIFICACIÓN | P2: TOTAL DE SEMANA
A3: 46286 | B3: 09:59:00 | C3: 14:06:00 | D3: 04:07:00 | K3: 04:07:00 | P3: 11.762292
A4: 46287 | B4: 09:38:00 | C4: 12:45:00 | D4: 03:07:00 | E4: 15:48:00 | F4: 17:50:00 | G4: 02:02:00 | K4: 05:09:00
A5: 46288 | B5: 09:56:00 | C5: 13:47:00 | D5: 03:51:00 | K5: 03:51:00
A6: 46289 | B6: 09:50:00 | C6: 13:48:00 | D6: 03:58:00 | K6: 03:58:00
A7: 46290 | B7: 09:26:00 | C7: 13:49:00 | D7: 04:23:00 | K7: 04:23:00
P9: =SUMPRODUCT(VALUE(K3:K7))-(SUM(L3:L7)) -> 0.89444444
A10: 46293 | B10: 10:04:27 | C10: 11:27:43 | D10: 01:23:16 | E10: 13:11:44 | F10: 14:25:54 | G10: =F10-E10 -> 0.05150463 | H10: 16:08:18 | I10: 16:57:55 | J10: 00:49:37 | K10: =D10+G10+J10 -> 0.14378472
A11: 46294 | B11: 10:07:08 | C11: 12:57:51 | D11: 02:50:43 | E11: 15:52:35 | F11: 0.70318287 | G11: =F11-E11 -> 0.041666667 | K11: =D11+G11+J11 -> 0.16021991
A12: 46295 | B12: 10:03:35 | C12: 13:57:06 | D12: 03:53:31 | G12: =F12-E12 -> 0 | K12: =D12+G12+J12 -> 0.16216435
A13: 46296 | G13: =F13-E13 -> 0 | K13: =D13+G13+J13 -> 0
A14: 46297 | B14: 09:41:44 | C14: 13:54:00 | D14: 04:12:16 | G14: =F14-E14 -> 0 | K14: =D14+G14+J14 -> 0.17518519
P16: =SUMPRODUCT(VALUE(K10:K14))-(SUM(L10:L14)) -> 0.64135417
A17: 46300 | B17: 10:08:30 | C17: 11:22:32 | D17: 01:14:02 | E17: 13:02:46 | F17: 14:26:55 | G17: 01:24:09 | H17: 16:09:49 | I17: 16:57:13 | J17: 00:47:24 | K17: 03:25:35
A18: 46301 | B18: 16:01:40 | C18: 17:05:43 | D18: 01:04:03 | K18: 01:04:03
A19: 46302 | B19: 09:54:31 | C19: 14:14:29 | D19: 04:19:58 | K19: 04:19:58
A20: 46303
A21: 46304
P23: =SUMPRODUCT(VALUE(K17:K21))-(SUM(L17:L21)) -> 0.36777778
A24: 46307
A25: 46308 | B25: 09:59:28 | C25: 12:52:54 | D25: 02:53:26 | E25: 16:05:47 | F25: 16:56:36 | G25: 00:50:49 | K25: 03:44:15
A26: 46309 | B26: 10:02:42 | C26: 14:09:23 | D26: 04:06:41 | K26: 04:06:41
A27: 46310 | B27: 09:50:25 | C27: 16:10:39 | D27: 06:20:14 | K27: 06:20:14 | N27: Tiempo Justificado
A28: 46311 | B28: 09:57:17 | C28: 13:58:20 | D28: 04:01:03 | K28: 04:01:03
P30: =SUMPRODUCT(VALUE(K24:K28))-(SUM(L24:L28)) -> 0.7584838
A31: 46314 | B31: 10:21:55 | C31: 11:26:24 | D31: 01:04:29 | E31: 13:07:21 | F31: 14:26:04 | G31: 01:18:43 | H31: 15:52:07 | I31: 16:56:35 | J31: 01:04:28 | K31: 03:27:40
A32: 46315 | B32: 09:53:18 | C32: 12:57:45 | D32: 03:04:27 | E32: 15:45:20 | F32: 17:00:12 | G32: 01:14:52 | K32: 04:19:19
A33: 46316 | B33: 10:02:50 | C33: 13:49:28 | D33: 03:46:38 | K33: 03:46:38
A34: 46317 | B34: 09:55:26 | D34: 00:00:00 | K34: 00:00:00
A35: 46318
P37: =SUMPRODUCT(VALUE(K31:K35))-(SUM(L31:L35)) -> 0.48167824
A38: 46321
A39: 46322
A40: 46323
A41: 46324
A42: 46325
P44: =SUMPRODUCT(VALUE(K38:K42))-(SUM(L38:L42)) -> 0
A45: 46328
A46: 46329
...

Sheet JAVIER G.S
A1: JAVIER GUERRERO SALAS | Q1: TOTAL CONTABILIZADO: | R1: =SUM(P:P) -> 20.015046
A2: FECHA | B2: ENTRADA 1 | C2: SALIDA 1 | D2: TOTAL 1 | E2: ENTRADA 2 | F2: SALIDA 2 | G2: TOTAL 2 | H2: ENTRADA 3 | I2: SALIDA 3 | J2: TOTAL 3 | K2: TOTAL HORAS DIARIAS | L2: AJUSTE (-) | N2: JUSTIFICACIÓN | P2: TOTAL DE SEMANA
A3: 46286 | P3: 19.44838
A4: 46287
A5: 46288 | B5: 13:01:00 | C5: 17:31:00 | D5: 04:30:00 | K5: 04:30:00
A6: 46289 | B6: 13:47:00 | C6: 18:26:00 | D6: 04:39:00 | K6: 04:39:00
A7: 46290 | B7: 13:33:00 | C7: 18:00:00 | D7: 04:27:00 | K7: 04:27:00
P9: =SUMPRODUCT(VALUE(K3:K7))-(SUM(L3:L7)) -> 0.56666667
A10: 46293
A11: 46294
A12: 46295
A13: 46296
A14: 46297
P16: =SUMPRODUCT(VALUE(K10:K14))-(SUM((L10:L14))) -> 0
A17: 46300
A18: 46301
A19: 46302
A20: 46303
A21: 46304
P23: =SUMPRODUCT(VALUE(K17:K21))-(SUM((L17:L21))) -> 0
A24: 46307
A25: 46308
A26: 46309
A27: 46310
A28: 46311
P30: =SUMPRODUCT(VALUE(K24:K28))-(SUM((L24:L28))) -> 0
A31: 46314
A32: 46315
A33: 46316
A34: 46317
A35: 46318
P37: =SUMPRODUCT(VALUE(K31:K35))-(SUM((L31:L35))) -> 0
A38: 46321
A39: 46322
A40: 46323
A41: 46324
A42: 46325
P44: =SUMPRODUCT(VALUE(K38:K42))-(SUM((L38:L42))) -> 0
A45: 46328
A46: 46329
...

Sheet KARLA Y.A.R
A1: KARLA YAMILET AGUILAR RAMÍREZ | Q1: TOTAL CONTABILIZADO: | R1: =SUM(P:P) -> 14.630428
A2: FECHA | B2: ENTRADA 1 | C2: SALIDA 1 | D2: TOTAL 1 | E2: ENTRADA 2 | F2: SALIDA 2 | G2: TOTAL 2 | H2: ENTRADA 3 | I2: SALIDA 3 | J2: TOTAL 3 | K2: TOTAL HORAS DIARIAS | L2: AJUSTE (-) | N2: JUSTIFICACIÓN | P2: TOTAL DE SEMANA
A3: 46286 | B3: 07:25:00 | C3: 11:17:00 | D3: 03:52:00 | K3: 03:52:00 | P3: 11.185579
A4: 46287 | B4: 11:59:00 | C4: 15:57:00 | D4: 03:58:00 | K4: 03:58:00
A5: 46288 | B5: 07:31:00 | C5: 11:22:00 | D5: 03:51:00 | K5: 03:51:00
A6: 46289 | B6: 12:14:00 | C6: 16:01:00 | D6: 03:47:00 | K6: 03:47:00
A7: 46290 | B7: 07:28:00 | C7: 11:11:00 | D7: 03:43:00 | K7: 03:43:00
P9: =SUMPRODUCT(VALUE(K3:K7))-(SUM(L3:L7)) -> 0.79930556
A10: 46293 | B10: 07:37:17 | C10: 11:30:11 | D10: 03:52:54 | K10: 03:52:54
A11: 46294 | B11: 12:00:13 | C11: 16:04:28 | D11: 04:04:15 | K11: 04:04:15
A12: 46295 | B12: 07:37:17 | C12: 11:36:10 | D12: 03:58:53 | K12: 03:58:53
A13: 46296 | B13: 09:57:08 | C13: 14:00:10 | D13: 04:03:02 | K13: 04:03:02
A14: 46297 | B14: 07:33:58 | C14: 11:31:06 | D14: 03:57:08 | K14: 03:57:08
P16: =SUMPRODUCT(VALUE(K10:K14))-(SUM(L10:L14)) -> 0.83069444
A17: 46300 | B17: 07:39:22 | C17: 11:40:05 | D17: 04:00:43 | K17: 04:00:43
A18: 46301 | B18: 12:00:35 | C18: 16:12:05 | D18: 04:11:30 | K18: 04:11:30
A19: 46302 | B19: 07:37:46 | C19: 11:31:35 | D19: 03:53:49 | K19: 03:53:49
A20: 46303 | B20: 12:09:25 | C20: 16:03:44 | D20: 03:54:19 | K20: 03:54:19
A21: 46304 | B21: 07:35:45 | C21: 11:34:43 | D21: 03:58:58 | K21: 03:58:58
P23: =SUMPRODUCT(VALUE(K17:K21))-(SUM(L17:L21)) -> 0.8328588
A24: 46307
A25: 46308
A26: 46309 | B26: 08:30:01 | C26: 11:29:43 | D26: 02:59:42 | K26: 02:59:42
A27: 46310
A28: 46311 | B28: 07:41:51 | C28: 13:10:08 | D28: 05:28:17 | K28: 05:28:17
P30: =SUMPRODUCT(VALUE(K24:K28))-(SUM(L24:L28)) -> 0.3527662
A31: 46314 | B31: 07:28:12 | C31: 13:01:06 | D31: 05:32:54 | K31: 05:32:54
A32: 46315 | B32: 12:00:53 | C32: 16:01:18 | D32: 04:00:25 | K32: 04:00:25
A33: 46316 | B33: 07:27:04 | C33: 11:30:17 | D33: 04:03:13 | E33: 12:59:12 | F33: 14:28:45 | G33: 01:29:33 | K33: 05:32:46
A34: 46317
A35: 46318
P37: =SUMPRODUCT(VALUE(K31:K35))-(SUM(L31:L35)) -> 0.62922454
A38: 46321
A39: 46322
A40: 46323
A41: 46324
A42: 46325
P44: =SUMPRODUCT(VALUE(K38:K42))-(SUM(L38:L42)) -> 0
A45: 46328
A46: 46329
...

Sheet KATHERINE M.M
A1: KATHERINE MENDEZ MARQUEZ | Q1: TOTAL CONTABILIZADO: | R1: =SUM(P:P) -> 20.142986
A2: FECHA | B2: ENTRADA 1 | C2: SALIDA 1 | D2: TOTAL 1 | E2: ENTRADA 2 | F2: SALIDA 2 | G2: TOTAL 2 | H2: ENTRADA 3 | I2: SALIDA 3 | J2: TOTAL 3 | K2: TOTAL HORAS DIARIAS | L2: AJUSTE (-) | N2: JUSTIFICACIÓN | P2: TOTAL DE SEMANA
A3: 46286 | B3: 09:51:00 | C3: 11:23:00 | D3: 01:32:00 | E3: 12:44:00 | F3: 14:26:00 | G3: 01:42:00 | H3: 16:31:00 | I3: 17:17:00 | J3: 00:46:00 | K3: 04:00:00 | P3: 17.058171
A4: 46287 | B4: 09:03:00 | C4: 09:55:00 | D4: 00:52:00 | K4: 00:52:00
A5: 46288 | B5: 09:42:00 | C5: 11:20:00 | D5: 01:38:00 | E5: 11:55:00 | F5: 14:18:00 | G5: 02:23:00 | H5: 15:49:00 | I5: 17:12:00 | J5: 01:23:00 | K5: 05:24:00
A6: 46289 | B6: 09:48:00 | C6: 15:17:00 | D6: 05:29:00 | K6: 05:29:00
A7: 46290 | B7: 12:48:00 | C7: 17:13:00 | D7: 04:25:00 | K7: 04:25:00
P9: =SUMPRODUCT(VALUE(K3:K7))-(SUM(L3:L7)) -> 0.84027778
A10: 46293 | B10: 10:00:07 | C10: 11:32:01 | D10: 01:31:54 | E10: 12:45:52 | F10: 14:32:00 | G10: 01:46:08 | H10: 15:53:44 | I10: 17:23:06 | J10: 01:29:22 | K10: 04:47:24
A11: 46294
A12: 46295 | B12: 09:56:02 | C12: 13:03:36 | D12: 03:07:34 | K12: 03:07:34
A13: 46296
A14: 46297 | B14: 10:04:37 | C14: 11:26:09 | D14: 01:21:32 | E14: 12:55:13 | F14: 14:32:53 | G14: 01:37:40 | H14: 16:10:24 | I14: 17:25:31 | J14: 01:15:07 | K14: 04:14:19
P16: =SUMPRODUCT(VALUE(K10:K14))-(SUM(L10:L14)) -> 0.50644676
A17: 46300 | B17: 09:55:57 | C17: 11:45:51 | D17: 01:49:54 | E17: 12:55:58 | F17: 17:15:17 | G17: 04:19:19 | K17: 06:09:13
A18: 46301
A19: 46302 | B19: 09:54:20 | C19: 11:25:45 | D19: 01:31:25 | E19: 13:02:06 | F19: 17:27:09 | G19: 04:25:03 | K19: 05:56:28
A20: 46303 | B20: 09:35:58 | C20: 14:09:59 | D20: 04:34:01 | K20: 04:34:01
A21: 46304 | B21: 09:59:26 | C21: 11:26:11 | D21: 01:26:45 | E21: 13:12:19 | F21: 14:29:19 | G21: 01:17:00 | H21: 15:50:44 | I21: 17:22:15 | J21: 01:31:31 | K21: 04:15:16
P23: =SUMPRODUCT(VALUE(K17:K21))-(SUM(L17:L21)) -> 0.87150463
A24: 46307
A25: 46308
A26: 46309 | B26: 09:58:32 | C26: 11:45:57 | D26: 01:47:25 | E26: 12:59:44 | F26: 17:24:59 | G26: 04:25:15 | K26: 06:12:40
A27: 46310 | B27: 10:00:01 | C27: 12:56:11 | D27: 02:56:10 | K27: 02:56:10
A28: 46311 | B28: 09:55:02 | D28: 00:00:00 | E28: 12:59:15 | F28: 14:30:51 | G28: 01:31:36 | H28: 15:44:59 | I28: 17:22:25 | J28: 01:37:26 | K28: 03:09:02
P30: =SUMPRODUCT(VALUE(K24:K28))-(SUM(L24:L28)) -> 0.51240741
A31: 46314 | B31: 09:54:18 | C31: 11:31:48 | D31: 01:37:30 | E31: 12:59:19 | F31: 17:33:38 | G31: 04:34:19 | K31: 06:11:49
A32: 46315
A33: 46316 | B33: 14:33:47 | C33: 16:51:59 | D33: 02:18:12 | K33: 02:18:12
A34: 46317
A35: 46318
P37: =SUMPRODUCT(VALUE(K31:K35))-(SUM(L31:L35)) -> 0.35417824
A38: 46321
A39: 46322
A40: 46323
A41: 46324
A42: 46325
P44: =SUMPRODUCT(VALUE(K38:K42))-(SUM(L38:L42)) -> 0
A45: 46328
A46: 46329
...

Sheet LUDWING P.C
A1: LUDWING PINEDA CUEVAS | Q1: TOTAL CONTABILIZADO: | R1: =SUM(P:P) -> 3.1560185
A2: FECHA | B2: ENTRADA 1 | C2: SALIDA 1 | D2: TOTAL 1 | E2: ENTRADA 2 | F2: SALIDA 2 | G2: TOTAL 2 | H2: ENTRADA 3 | I2: SALIDA 3 | J2: TOTAL 3 | K2: TOTAL HORAS DIARIAS | L2: AJUSTE (-) | N2: JUSTIFICACIÓN | P2: TOTAL DE SEMANA
A3: 46286 | D3: =C3-B3 -> 0 | K3: =D3+G3+J3 -> 0
A4: 46287 | D4: =C4-B4 -> 0 | K4: =D4+G4+J4 -> 0
A5: 46288 | B5: 15:50:00 | C5: 19:50:00 | D5: =C5-B5 -> 0.16666667 | K5: =D5+G5+J5 -> 0.16666667
A6: 46289 | B6: 10:46:00 | C6: 14:51:00 | D6: =C6-B6 -> 0.17013889 | K6: =D6+G6+J6 -> 0.17013889
A7: 46290 | B7: 15:49:00 | C7: 19:52:00 | D7: =C7-B7 -> 0.16875 | K7: =D7+G7+J7 -> 0.16875
P9: =SUMPRODUCT(VALUE(K3:K7))-(SUM(L3:L7)) -> 0.50555556
A10: 46293 | B10: 15:59:27 | C10: 19:55:17 | D10: =C10-B10 -> 0.16377315 | K10: =D10+G10+J10 -> 0.16377315
A11: 46294 | B11: 12:01:04 | C11: 17:01:02 | D11: =C11-B11 -> 0.20831019 | K11: =D11+G11+J11 -> 0.20831019
A12: 46295 | B12: 15:55:09 | C12: 19:59:14 | D12: =C12-B12 -> 0.16950231 | K12: =D12+G12+J12 -> 0.16950231 | L12: 0.0028356481
A13: 46296 | B13: 10:58:11 | C13: 14:50:28 | D13: =C13-B13 -> 0.16130787 | K13: =D13+G13+J13 -> 0.16130787
A14: 46297 | B14: 15:37:16 | C14: 19:55:17 | D14: =C14-B14 -> 0.17917824 | K14: =D14+G14+J14 -> 0.17917824 | L14: 0.012511574
P16: =SUMPRODUCT(VALUE(K10:K14))-(SUM(L10:L14)) -> 0.86672454
A17: 46300 | B17: 16:01:48 | C17: 19:51:12 | D17: 03:49:24 | K17: 03:49:24
A18: 46301
A19: 46302 | B19: 16:00:02 | C19: 19:58:16 | D19: 03:58:14 | K19: 03:58:14
A20: 46303 | B20: 11:01:18 | C20: 15:03:09 | D20: 04:01:51 | K20: 04:01:51
A21: 46304 | B21: 16:02:22 | C21: 20:02:51 | D21: 04:00:29 | K21: 04:00:29
P23: =SUMPRODUCT(VALUE(K17:K21))-(SUM(L17:L21)) -> 0.65969907
A24: 46307
A25: 46308 | B25: 11:53:02 | C25: 17:00:41 | D25: 05:07:39 | K25: 05:07:39 | N25: Tiempo Justificado
A26: 46309 | B26: 16:04:23 | C26: 20:10:23 | D26: 04:06:00 | K26: 04:06:00
A27: 46310 | B27: 11:31:06 | C27: 15:08:59 | D27: 03:37:53 | K27: 03:37:53
A28: 46311 | B28: 14:50:33 | C28: 20:04:51 | D28: 05:14:18 | K28: 05:14:18 | N28: Tiempo Justificado
P30: =SUMPRODUCT(VALUE(K24:K28))-(SUM(L24:L28)) -> 0.75405093
A31: 46314 | B31: 16:11:23 | C31: 20:00:12 | D31: 03:48:49 | K31: 03:48:49
A32: 46315 | B32: 11:56:43 | C32: 17:00:41 | D32: 05:03:58 | K32: 05:03:58
A33: 46316 | B33: 15:57:36 | D33: 00:00:00 | K33: 00:00:00
A34: 46317
A35: 46318
P37: =SUMPRODUCT(VALUE(K31:K35))-(SUM(L31:L35)) -> 0.36998843
A38: 46321
A39: 46322
A40: 46323
A41: 46324
A42: 46325
P44: =SUMPRODUCT(VALUE(K38:K42))-(SUM(L38:L42)) -> 0
A45: 46328
A46: 46329
...

Sheet LUIS F.C.G
A1: LUIS FERNANDO CASTILLO GARCÍA | Q1: TOTAL CONTABILIZADO: | R1: =SUM(P:P) -> 15.661076
A2: FECHA | B2: ENTRADA 1 | C2: SALIDA 1 | D2: TOTAL 1 | E2: ENTRADA 2 | F2: SALIDA 2 | G2: TOTAL 2 | H2: ENTRADA 3 | I2: SALIDA 3 | J2: TOTAL 3 | K2: TOTAL HORAS DIARIAS | L2: AJUSTE (-) | N2: JUSTIFICACIÓN | P2: TOTAL DE SEMANA
A3: 46286 | B3: 14:23:00 | C3: 18:32:00 | D3: 04:09:00 | K3: 04:09:00 | L3: 0.00625 | P3: 11.987523
A4: 46287 | B4: 08:06:00 | C4: 12:14:00 | D4: 04:08:00 | K4: 04:08:00 | L4: 0.0055555556
A5: 46288 | B5: 14:18:00 | C5: 18:27:00 | D5: 04:09:00 | K5: 04:09:00 | L5: 0.00625
A6: 46289 | B6: 08:13:00 | C6: 12:13:00 | D6: 04:00:00 | K6: 04:00:00
A7: 46290 | B7: 08:37:00 | C7: 13:11:00 | D7: 04:34:00 | K7: 04:34:00 | L7: 0.023611111
P9: =SUMPRODUCT(VALUE(K3:K7))-(SUM(L3:L7)) -> 0.83333333
A10: 46293 | B10: 14:43:39 | C10: 18:55:53 | D10: 04:12:14 | K10: 04:12:14 | L10: 0.0084953704 | N10: Tiempo no justificado
A11: 46294 | B11: 08:02:27 | C11: 11:04:30 | D11: 03:02:03 | E11: 12:40:10 | F11: 13:47:27 | G11: 01:07:17 | K11: 04:09:20 | L11: 0.0064814815 | N11: Tiempo no justificado
A12: 46295 | B12: 14:28:44 | C12: 18:31:56 | D12: 04:03:12 | K12: 04:03:12 | L12: 0.0024421296 | N12: Tiempo no justificado
A13: 46296 | B13: 08:14:45 | C13: 12:22:16 | D13: 04:07:31 | K13: 04:07:31 | L13: 0.0052199074 | N13: Tiempo no justificado
A14: 46297 | B14: 08:57:03 | C14: 12:57:52 | D14: 04:00:49 | K14: 04:00:49
P16: =SUMPRODUCT(VALUE(K10:K14))-(SUM(L10:L14)) -> 0.83368056
A17: 46300 | B17: 14:43:14 | C17: 18:47:38 | D17: 04:04:24 | K17: 04:04:24
A18: 46301 | B18: 08:24:09 | C18: 12:28:38 | D18: 04:04:29 | K18: 04:04:29
A19: 46302 | B19: 14:36:14 | C19: 18:45:27 | D19: 04:09:13 | K19: 04:09:13
A20: 46303 | B20: 08:52:14 | C20: 12:53:23 | D20: 04:01:09 | K20: 04:01:09
A21: 46304 | B21: 08:57:43 | C21: 13:00:04 | D21: 04:02:21 | K21: 04:02:21
P23: =SUMPRODUCT(VALUE(K17:K21))-(SUM(L17:L21)) -> 0.84833333
A24: 46307
A25: 46308 | B25: 08:39:40 | C25: 12:44:12 | D25: 04:04:32 | K25: 04:04:32
A26: 46309 | B26: 14:39:46 | C26: 18:41:10 | D26: 04:01:24 | K26: 04:01:24
A27: 46310 | B27: 08:51:02 | C27: 12:50:45 | D27: 03:59:43 | K27: 03:59:43
A28: 46311 | B28: 16:39:09 | C28: 20:02:32 | D28: 03:23:23 | K28: 03:23:23
P30: =SUMPRODUCT(VALUE(K24:K28))-(SUM(L24:L28)) -> 0.64516204
A31: 46314 | B31: 14:44:43 | C31: 18:50:17 | D31: 04:05:34 | K31: 04:05:34
A32: 46315 | B32: 08:30:59 | C32: 12:36:45 | D32: 04:05:46 | K32: 04:05:46
A33: 46316 | B33: 14:42:35 | C33: 18:50:02 | D33: 04:07:27 | K33: 04:07:27
A34: 46317 | B34: 08:47:06 | D34: 00:00:00 | K34: 00:00:00
A35: 46318
P37: =SUMPRODUCT(VALUE(K31:K35))-(SUM(L31:L35)) -> 0.51304398
A38: 46321
A39: 46322
A40: 46323
A41: 46324
A42: 46325
P44: =SUMPRODUCT(VALUE(K38:K42))-(SUM(L38:L42)) -> 0
A45: 46328
A46: 46329
...

Sheet MARIA N.C.M
A1: MARIA NATALIA CABRERA MONJARAS | Q1: TOTAL CONTABILIZADO: | R1: =SUM(P:P) -> 13.335706
A2: FECHA | B2: ENTRADA 1 | C2: SALIDA 1 | D2: TOTAL 1 | E2: ENTRADA 2 | F2: SALIDA 2 | G2: TOTAL 2 | H2: ENTRADA 3 | I2: SALIDA 3 | J2: TOTAL 3 | K2: TOTAL HORAS DIARIAS | L2: AJUSTE (-) | N2: JUSTIFICACIÓN | P2: TOTAL DE SEMANA
A3: 46286 | B3: 17:15:00 | C3: 18:59:00 | D3: 01:44:00 | K3: 01:44:00 | P3: 9.8787847
A4: 46287 | B4: 07:05:00 | C4: 09:47:00 | D4: 02:42:00 | E4: 10:36:00 | F4: 12:37:00 | G4: 02:01:00 | K4: 04:43:00
A5: 46288 | B5: 09:52:00 | C5: 11:23:00 | D5: 01:31:00 | E5: 15:53:00 | F5: 18:55:00 | G5: 03:02:00 | K5: 04:33:00
A6: 46289 | B6: 08:03:00 | C6: 11:52:00 | D6: 03:49:00 | K6: 03:49:00
A7: 46290 | B7: 09:57:00 | C7: 12:19:00 | D7: 02:22:00 | E7: 16:09:00 | F7: 19:12:00 | G7: 03:03:00 | K7: 05:25:00
P9: =SUMPRODUCT(VALUE(K3:K7))-(SUM(L3:L7)) -> 0.84305556
A10: 46293 | B10: 17:07:23 | C10: 18:50:58 | D10: =C10-B10 -> 0.07193287 | K10: =D10+G10+J10 -> 0.07193287
A11: 46294 | B11: 08:16:49 | C11: 13:34:17 | D11: =C11-B11 -> 0.22046296 | K11: =D11+G11+J11 -> 0.22046296 | N11: Tiempo justificado
A12: 46295 | B12: 09:53:12 | C12: 11:23:00 | D12: =C12-B12 -> 0.062361111 | E12: 16:00:06 | F12: 18:56:59 | G12: 02:56:53 | K12: =D12+G12+J12 -> 0.18519676
A13: 46296 | B13: 08:24:02 | C13: 09:00:47 | D13: =C13-B13 -> 0.025520833 | E13: 09:57:00 | F13: 12:50:45 | G13: 02:53:45 | H13: 13:03:23 | I13: 14:00:13 | J13: 00:56:50 | K13: =D13+G13+J13 -> 0.18564815 | N13: Tiempo justificado
A14: 46297 | B14: 09:54:19 | C14: 11:38:23 | D14: =C14-B14 -> 0.072268519 | E14: 15:58:35 | F14: 19:02:07 | G14: 03:03:32 | K14: =D14+G14+J14 -> 0.19972222 | N14: Tiempo justificado
P16: =SUMPRODUCT(VALUE(K10:K14))-(SUM(L10:L14)) -> 0.86296296
A17: 46300 | B17: 17:26:19 | C17: 19:04:08 | D17: 01:37:49 | K17: 01:37:49
A18: 46301 | B18: 07:30:26 | C18: 09:46:54 | D18: 02:16:28 | E18: 12:38:39 | F18: 15:02:13 | G18: 02:23:34 | K18: 04:40:02
A19: 46302
A20: 46303 | B20: 08:28:26 | C20: 12:35:12 | D20: 04:06:46 | K20: 04:06:46
A21: 46304 | B21: 10:00:03 | C21: 11:32:31 | D21: 01:32:28 | E21: 15:59:50 | F21: 19:01:02 | G21: 03:01:12 | K21: 04:33:40
P23: =SUMPRODUCT(VALUE(K17:K21))-(SUM(L17:L21)) -> 0.62380787
A24: 46307
A25: 46308 | B25: 07:28:13 | C25: 10:01:58 | D25: 02:33:45 | E25: 11:57:56 | F25: 15:01:11 | G25: 03:03:15 | K25: 05:37:00 | N25: Tiempo Justificado
A26: 46309 | B26: 10:02:13 | C26: 11:29:59 | D26: 01:27:46 | E26: 16:24:12 | F26: 18:54:25 | G26: 02:30:13 | K26: 03:57:59
A27: 46310
A28: 46311 | B28: 0.41666667 | C28: 0.47916667 | D28: =C28-B28 -> 0.0625 | E28: 0.66527778 | F28: 0.83333333 | G28: =F28-E28 -> 0.16805556 | K28: =D28+G28 -> 0.23055556 | N28: Tiempo Justificado
P30: =SUMPRODUCT(VALUE(K24:K28))-(SUM(L24:L28)) -> 0.62984954
A31: 46314 | B31: 10:04:32 | C31: 10:05:47 | D31: 00:01:15 | E31: 17:26:35 | F31: 19:02:49 | G31: 01:36:14 | H31: 20:19:48 | I31: 21:00:18 | J31: 00:40:30 | K31: 02:17:59
A32: 46315 | B32: 06:53:27 | C32: 09:58:29 | D32: 03:05:02 | E32: 12:55:53 | F32: 14:59:46 | G32: 02:03:53 | K32: 05:08:55
A33: 46316 | B33: 09:57:08 | C33: 11:30:45 | D33: 01:33:37 | E33: 15:58:40 | F33: 18:54:11 | G33: 02:55:31 | K33: 04:29:08
A34: 46317 | B34: 09:03:22 | D34: 00:00:00 | K34: 00:00:00
A35: 46318
P37: =SUMPRODUCT(VALUE(K31:K35))-(SUM(L31:L35)) -> 0.49724537
A38: 46321
A39: 46322
A40: 46323
A41: 46324
A42: 46325
P44: =SUMPRODUCT(VALUE(K38:K42))-(SUM(L38:L42)) -> 0
A45: 46328
A46: 46329
...

Sheet MISAEL R.L
A1: MISAEL RIVERA LÓPEZ | Q1: TOTAL CONTABILIZADO: | R1: =SUM(P:P) -> 9.0679977
A2: FECHA | B2: ENTRADA 1 | C2: SALIDA 1 | D2: TOTAL 1 | E2: ENTRADA 2 | F2: SALIDA 2 | G2: TOTAL 2 | H2: ENTRADA 3 | I2: SALIDA 3 | J2: TOTAL 3 | K2: TOTAL HORAS DIARIAS | L2: AJUSTE (-) | N2: JUSTIFICACIÓN | P2: TOTAL DE SEMANA
A3: 46286 | P3: 6.3049884
A4: 46287 | B4: 15:46:00 | C4: 19:51:00 | D4: 04:05:00 | K4: 04:05:00
A5: 46288 | B5: 10:06:00 | C5: 11:20:00 | D5: 01:14:00 | E5: 15:58:00 | F5: 19:51:00 | G5: 03:53:00 | K5: 05:07:00
A6: 46289 | B6: 13:16:00 | C6: 14:19:00 | D6: 01:03:00 | E6: 15:59:00 | F6: 19:52:00 | G6: 03:53:00 | K6: 04:56:00
A7: 46290 | B7: 12:42:00 | C7: 13:55:00 | D7: 01:13:00 | E7: 15:58:00 | F7: 20:04:00 | G7: 04:06:00 | K7: 05:19:00
P9: =SUMPRODUCT(VALUE(K3:K7))-(SUM(L3:L7)) -> 0.81041667
A10: 46293 | B10: 16:03:49 | C10: 20:06:39 | D10: =C10-B10 -> 0.16863426 | K10: =D10+G10+J10 -> 0.16863426
A11: 46294 | B11: 16:06:55 | C11: 20:06:39 | D11: =C11-B11 -> 0.16648148 | K11: =D11+G11+J11 -> 0.16648148
A12: 46295 | B12: 16:07:30 | C12: 20:06:36 | D12: =C12-B12 -> 0.16604167 | K12: =D12+G12+J12 -> 0.16604167
A13: 46296 | B13: 16:07:30 | C13: 20:06:36 | D13: =C13-B13 -> 0.16604167 | K13: =D13+G13+J13 -> 0.16604167
A14: 46297 | B14: 16:02:55 | C14: 20:01:18 | D14: =C14-B14 -> 0.16554398 | K14: =D14+G14+J14 -> 0.16554398
P16: =SUMPRODUCT(VALUE(K10:K14))-(SUM(L10:L14)) -> 0.83274306
A17: 46300 | B17: 15:57:59 | C17: 20:06:56 | D17: 04:08:57 | K17: 04:08:57
A18: 46301 | B18: 16:09:34 | C18: 20:07:31 | D18: 03:57:57 | K18: 03:57:57
A19: 46302
A20: 46303
A21: 46304 | B21: 16:05:54 | C21: 20:06:07 | D21: 04:00:13 | K21: 04:00:13
P23: =SUMPRODUCT(VALUE(K17:K21))-(SUM(L17:L21)) -> 0.50494213
A24: 46307
A25: 46308 | B25: 16:02:40 | C25: 20:00:57 | D25: 03:58:17 | K25: 03:58:17
A26: 46309
A27: 46310 | B27: 15:39:22 | C27: 20:02:01 | D27: 04:22:39 | K27: 04:22:39
A28: 46311 | B28: 15:59:29 | C28: 20:00:44 | D28: 04:01:15 | K28: 04:01:15
P30: =SUMPRODUCT(VALUE(K24:K28))-(SUM(L24:L28)) -> 0.51540509
A31: 46314 | B31: 16:05:38 | D31: 00:00:00 | K31: 00:00:00
A32: 46315 | B32: 16:12:52 | D32: 00:00:00 | K32: 00:00:00
A33: 46316 | B33: 08:53:52 | C33: 11:17:09 | D33: 02:23:17 | E33: 16:02:44 | G33: 00:00:00 | K33: 02:23:17
A34: 46317
A35: 46318
P37: =SUMPRODUCT(VALUE(K31:K35))-(SUM(L31:L35)) -> 0.099502315
A38: 46321
A39: 46322
A40: 46323
A41: 46324
A42: 46325
P44: =SUMPRODUCT(VALUE(K38:K42))-(SUM(L38:L42)) -> 0
A45: 46328
A46: 46329
...

Sheet RAFAEL E.L.G
A1: RAFAEL EDUARDO LAGUNAS GÓMEZ | Q1: TOTAL CONTABILIZADO: | R1: =SUM(P:P) -> 15.218137
A2: FECHA | B2: ENTRADA 1 | C2: SALIDA 1 | D2: TOTAL 1 | E2: ENTRADA 2 | F2: SALIDA 2 | G2: TOTAL 2 | H2: ENTRADA 3 | I2: SALIDA 3 | J2: TOTAL 3 | K2: TOTAL HORAS DIARIAS | L2: AJUSTE (-) | N2: JUSTIFICACIÓN | P2: TOTAL DE SEMANA
A3: 46286 | B3: 09:32:00 | C3: 13:55:00 | D3: 04:23:00 | K3: 04:23:00 | L3: 0.015972222 | P3: 11.389525
A4: 46287 | B4: 09:51:00 | C4: 13:53:00 | D4: 04:02:00 | K4: 04:02:00 | L4: 0.0013888889
A5: 46288 | B5: 09:25:00 | C5: 14:17:00 | D5: 04:52:00 | K5: 04:52:00
A6: 46289 | B6: 07:04:00 | C6: 11:04:00 | D6: 04:00:00 | K6: 04:00:00
A7: 46290 | B7: 09:41:00 | C7: 13:51:00 | D7: 04:10:00 | K7: 04:10:00 | L7: 0.0069444444
P9: =SUMPRODUCT(VALUE(K3:K7))-(SUM(L3:L7)) -> 0.86944444
A10: 46293 | B10: 09:46:00 | C10: 14:04:28 | D10: 04:18:28 | K10: 04:18:28 | L10: 0.012824074
A11: 46294 | B11: 09:33:47 | C11: 14:00:24 | D11: 04:26:37 | K11: 04:26:37 | L11: 0.018483796
A12: 46295 | B12: 09:29:52 | C12: 14:05:56 | D12: 04:36:04 | K12: 04:36:04 | L12: 0.025046296
A13: 46296 | B13: 06:58:52 | C13: 11:01:50 | D13: 04:02:58 | K13: 04:02:58 | L13: 0.0020601852
A14: 46297 | B14: 09:41:32 | C14: 14:16:53 | D14: 04:35:21 | K14: 04:35:21 | L14: 0.024548611
P16: =SUMPRODUCT(VALUE(K10:K14))-(SUM(L10:L14)) -> 0.83333333
A17: 46300 | B17: 09:28:29 | C17: 14:05:30 | D17: 04:37:01 | K17: 04:37:01 | L17: 0.025706019 | N17: Tiempo no justificado
A18: 46301 | B18: 09:26:31 | C18: 14:03:11 | D18: 04:36:40 | K18: 04:36:40 | L18: 0.025462963 | N18: Tiempo no justificado
A19: 46302 | B19: 10:05:03 | C19: 14:15:13 | D19: 04:10:10 | K19: 04:10:10
A20: 46303 | B20: 09:27:56 | C20: 14:00:02 | D20: 04:32:06 | K20: 04:32:06 | L20: 0.022291667 | N20: Tiempo no justificado
A21: 46304 | B21: 09:32:08 | C21: 14:10:13 | D21: 04:38:05 | K21: 04:38:05 | L21: 0.026446759 | N21: Tiempo no justificado
P23: =SUMPRODUCT(VALUE(K17:K21))-(SUM(L17:L21)) -> 0.84039352
A24: 46307
A25: 46308 | B25: 09:18:54 | C25: 15:00:04 | D25: 05:41:10 | K25: 05:41:10 | N25: Tiempo Justificado
A26: 46309 | B26: 09:34:16 | C26: 14:01:13 | D26: 04:26:57 | K26: 04:26:57 | L26: 0.018715278 | N26: Tiempo no justificado
A27: 46310 | B27: 09:55:19 | C27: 14:10:53 | D27: 04:15:34 | K27: 04:15:34 | L27: 0.010810185 | N27: Tiempo no justificado
A28: 46311 | B28: 09:56:02 | C28: 14:02:17 | D28: 04:06:15 | K28: 04:06:15
P30: =SUMPRODUCT(VALUE(K24:K28))-(SUM(L24:L28)) -> 0.74126157
A31: 46314 | B31: 09:32:17 | C31: 14:03:30 | D31: 04:31:13 | K31: 04:31:13
A32: 46315 | B32: 07:26:42 | C32: 11:29:58 | D32: 04:03:16 | K32: 04:03:16
A33: 46316 | B33: 09:32:45 | C33: 14:01:53 | D33: 04:29:08 | K33: 04:29:08
A34: 46317 | B34: 09:28:06 | D34: 00:00:00 | K34: 00:00:00
A35: 46318
P37: =SUMPRODUCT(VALUE(K31:K35))-(SUM(L31:L35)) -> 0.54417824
A38: 46321
A39: 46322
A40: 46323
A41: 46324
A42: 46325
P44: =SUMPRODUCT(VALUE(K38:K42))-(SUM(L38:L42)) -> 0
A45: 46328
A46: 46329
...

Sheet CARLOS C.T.M
A1: CARLOS CRISTOPHER TERRAZAS MARTINEZ | Q1: TOTAL CONTABILIZADO: | R1: =SUM(P:P) -> 2.5592477
A2: FECHA | B2: ENTRADA 1 | C2: SALIDA 1 | D2: TOTAL 1 | E2: ENTRADA 2 | F2: SALIDA 2 | G2: TOTAL 2 | H2: ENTRADA 3 | I2: SALIDA 3 | J2: TOTAL 3 | K2: TOTAL HORAS DIARIAS | L2: AJUSTE (-) | N2: JUSTIFICACIÓN | P2: TOTAL DE SEMANA
A3: 46286
A4: 46287
A5: 46288
A6: 46289
A7: 46290
P9: =SUMPRODUCT(VALUE(K3:K7))-(SUM(L3:L7)) -> 0
A10: 46293 | B10: 0.5 | C10: 0.60416667 | D10: =C10-B10 -> 0.10416667 | E10: 16:08:42 | F10: 17:50:18 | G10: =F10-E10 -> 0.070555556 | K10: =D10+G10+J10 -> 0.17472222 | L10: 0.0080555556
A11: 46294 | B11: 12:03:48 | C11: 16:00:57 | D11: =C11-B11 -> 0.1646875 | G11: =F11-E11 -> 0 | K11: =D11+G11+J11 -> 0.1646875
A12: 46295 | B12: 12:14:56 | C12: 14:31:15 | D12: =C12-B12 -> 0.094664352 | E12: 16:08:42 | F12: 17:50:18 | G12: =F12-E12 -> 0.070555556 | K12: =D12+G12+J12 -> 0.16521991
A13: 46296 | B13: 12:20:44 | C13: 16:21:11 | D13: =C13-B13 -> 0.16697917 | G13: =F13-E13 -> 0 | K13: =D13+G13+J13 -> 0.16697917
A14: 46297 | B14: 12:10:55 | C14: 17:30:43 | D14: =C14-B14 -> 0.22208333 | G14: =F14-E14 -> 0 | K14: =D14+G14+J14 -> 0.22208333 | L14: 0.01375 | N14: Hora Justificada
P16: =SUMPRODUCT(VALUE(K10:K14))-(SUM(L10:L14)) -> 0.87188657
A17: 46300 | B17: 13:03:00 | C17: 14:43:51 | D17: 01:40:51 | E17: 15:53:29 | F17: 17:30:05 | G17: 01:36:36 | K17: 03:17:27 | L17: 0.012118056
A18: 46301 | B18: 12:10:41 | C18: 16:09:52 | D18: 03:59:11 | K18: 03:59:11
A19: 46302 | B19: 11:54:40 | C19: 14:30:58 | D19: 02:36:18 | E19: 15:56:08 | F19: 17:28:27 | G19: 01:32:19 | K19: 04:08:37
A20: 46303 | B20: 12:14:16 | C20: 17:01:01 | D20: 04:46:45 | K20: 04:46:45
A21: 46304
P23: =SUMPRODUCT(VALUE(K17:K21))-(SUM(L17:L21)) -> 0.66288194
A24: 46307
A25: 46308 | B25: 11:53:08 | C25: 16:00:07 | D25: 04:06:59 | K25: 04:06:59
A26: 46309 | B26: 11:57:00 | C26: 14:24:18 | D26: 02:27:18 | E26: 15:54:49 | F26: 17:29:32 | G26: 01:34:43 | K26: 04:02:01
A27: 46310 | B27: 11:51:53 | C27: 16:05:45 | D27: 04:13:52 | K27: 04:13:52
A28: 46311 | B28: 11:53:59 | C28: 14:23:22 | D28: 02:29:23 | E28: 15:59:52 | F28: 17:29:47 | G28: 01:29:55 | K28: 03:59:18
P30: =SUMPRODUCT(VALUE(K24:K28))-(SUM(L24:L28)) -> 0.68206019
A31: 46314 | B31: 12:10:39 | C31: 14:32:17 | D31: 02:21:38 | E31: 15:55:31 | F31: 17:32:31 | G31: 01:37:00 | K31: 03:58:38
A32: 46315 | C32: 16:02:14 | D32: 00:00:00 | K32: 00:00:00
A33: 46316 | B33: 11:57:25 | C33: 14:31:05 | D33: 02:33:40 | E33: 15:50:17 | F33: 17:31:04 | G33: 01:40:47 | K33: 04:14:27
A34: 46317
A35: 46318
P37: =SUMPRODUCT(VALUE(K31:K35))-(SUM(L31:L35)) -> 0.34241898
A38: 46321
A39: 46322
A40: 46323
A41: 46324
A42: 46325
P44: =SUMPRODUCT(VALUE(K38:K42))-(SUM(L38:L42)) -> 0
A45: 46328
A46: 46329
...
